Workbook

Sheet Function
A2: List of function | B2: Details
A3: PV | B3: Present Value
A4: FV | B4: Future Value
A5: PMT | B5: calculates the payment for a loan based on constant payments and a constant interest rate.
A6: NPER | B6: Returns the number of periods for an investment based on periodic, constant payments and a constant interest rate.

Sheet Amortization Schedule
A1: Input | B1: Amount
A2: Loan Principal (A) | B2: 10000
A3: Interest Rate (i) | B3: 0.1
A4: Term (n) | B4: 5
A5: Annual Installment (R) | B5: =PMT(B3,B4,-B2) -> 2637.9748
A7: Period | B7: Opening Balance | C7: Installment (R) | D7: Interest (I) | E7: Principal Repaid (P) | F7: Closing Balance
A8: 0 | F8: =B2 -> 10000
A9: 1 | B9: =F8 -> 10000 | C9: =$B$5 -> 2637.9748 | D9: =B9*$B$3 -> 1000 | E9: =C9-D9 -> 1637.9748 | F9: =B9-E9 -> 8362.0252
A10: 2 | B10: =F9 -> 8362.0252 | C10: =$B$5 -> 2637.9748 | D10: =B10*$B$3 -> 836.20252 | E10: =C10-D10 -> 1801.7723 | F10: =B10-E10 -> 6560.2529
A11: 3 | B11: =F10 -> 6560.2529 | C11: =$B$5 -> 2637.9748 | D11: =B11*$B$3 -> 656.02529 | E11: =C11-D11 -> 1981.9495 | F11: =B11-E11 -> 4578.3034
A12: 4 | B12: =F11 -> 4578.3034 | C12: =$B$5 -> 2637.9748 | D12: =B12*$B$3 -> 457.83034 | E12: =C12-D12 -> 2180.1445 | F12: =B12-E12 -> 2398.1589
A13: 5 | B13: =F12 -> 2398.1589 | C13: =$B$5 -> 2637.9748 | D13: =B13*$B$3 -> 239.81589 | E13: =C13-D13 -> 2398.1589 | F13: =B13-E13 -> 0
D14: =SUBTOTAL(109,Table2[Interest (I)]) -> 3189.874 | E14: =SUBTOTAL(109,Table2[Principal Repaid (P)]) -> 10000

Sheet Student_Amortization Schedule
A5: Input | B5: Amount
A6: Loan Principal (A) | B6: 10000
A7: Interest Rate (i) | B7: 0.1
A8: Term (n) | B8: 5
A9: Annual Installment (R) | B9: =PMT(B7,B8,-B6) -> 2637.9748
A12: Period | B12: Opening Balance | C12: Installment (R) | D12: Interest (I) | E12: Principal Repaid (P) | F12: Closing Balance
A13: 0 | D13: =$B$7*Table215[[#This Row],[Opening Balance]] -> 0 | E13: =Table215[[#This Row],[Installment (R)]]-Table215[[#This Row],[Interest (I)]] -> 0 | F13: =B6 -> 10000
A14: 1 | B14: =F13 -> 10000 | C14: =$B$9 -> 2637.9748 | D14: =$B$7*Table215[[#This Row],[Opening Balance]] -> 1000 | E14: =Table215[[#This Row],[Installment (R)]]-Table215[[#This Row],[Interest (I)]] -> 1637.9748 | F14: =Table215[[#This Row],[Opening Balance]]-Table215[[#This Row],[Principal Repaid (P)]] -> 8362.0252
A15: 2 | B15: =F14 -> 8362.0252 | C15: =$B$9 -> 2637.9748 | D15: =$B$7*Table215[[#This Row],[Opening Balance]] -> 836.20252 | E15: =Table215[[#This Row],[Installment (R)]]-Table215[[#This Row],[Interest (I)]] -> 1801.7723 | F15: =Table215[[#This Row],[Opening Balance]]-Table215[[#This Row],[Principal Repaid (P)]] -> 6560.2529
A16: 3 | B16: =F15 -> 6560.2529 | C16: =$B$9 -> 2637.9748 | D16: =$B$7*Table215[[#This Row],[Opening Balance]] -> 656.02529 | E16: =Table215[[#This Row],[Installment (R)]]-Table215[[#This Row],[Interest (I)]] -> 1981.9495 | F16: =Table215[[#This Row],[Opening Balance]]-Table215[[#This Row],[Principal Repaid (P)]] -> 4578.3034
A17: 4 | B17: =F16 -> 4578.3034 | C17: =$B$9 -> 2637.9748 | D17: =$B$7*Table215[[#This Row],[Opening Balance]] -> 457.83034 | E17: =Table215[[#This Row],[Installment (R)]]-Table215[[#This Row],[Interest (I)]] -> 2180.1445 | F17: =Table215[[#This Row],[Opening Balance]]-Table215[[#This Row],[Principal Repaid (P)]] -> 2398.1589
A18: 5 | B18: =F17 -> 2398.1589 | C18: =$B$9 -> 2637.9748 | D18: =$B$7*Table215[[#This Row],[Opening Balance]] -> 239.81589 | E18: =Table215[[#This Row],[Installment (R)]]-Table215[[#This Row],[Interest (I)]] -> 2398.1589 | F18: =Table215[[#This Row],[Opening Balance]]-Table215[[#This Row],[Principal Repaid (P)]] -> 0
D19: =SUBTOTAL(109,Table215[Interest (I)]) -> 3189.874 | E19: =SUBTOTAL(109,Table215[Principal Repaid (P)]) -> 10000

Sheet Sheet1
A1: Period | B1: Opening Balance | C1: Installment (R) | D1: Interest (I) | E1: Principal Repaid (P) | F1: Closing Balance | J1: Input | K1: Amount
A2: 0 | B2: =F1 -> Closing Balance | F2: =Table11425[[#This Row],[Amount]] -> 10000 | J2: Loan Principal (A) | K2: 10000
A3: 1 | B3: =F2 -> 10000 | C3: =$K$5 -> 2637.9748 | D3: =0.1*Sheet1!$B3 -> 1000 | E3: =Sheet1!$C3-Sheet1!$D3 -> 1637.9748 | F3: =Sheet1!$B3-Sheet1!$E3 -> 8362.0252 | J3: Interest Rate (i) | K3: 0.1
A4: 2 | B4: =F3 -> 8362.0252 | C4: =$K$5 -> 2637.9748 | D4: =0.1*Sheet1!$B4 -> 836.20252 | E4: =Sheet1!$C4-Sheet1!$D4 -> 1801.7723 | F4: =Sheet1!$B4-Sheet1!$E4 -> 6560.2529 | J4: Term (n) | K4: 5
A5: 3 | B5: =F4 -> 6560.2529 | C5: =$K$5 -> 2637.9748 | D5: =0.1*Sheet1!$B5 -> 656.02529 | E5: =Sheet1!$C5-Sheet1!$D5 -> 1981.9495 | F5: =Sheet1!$B5-Sheet1!$E5 -> 4578.3034 | J5: Annual Installment (R) | K5: =PMT(K3,K4,-K2) -> 2637.9748
A6: 4 | B6: =F5 -> 4578.3034 | C6: =$K$5 -> 2637.9748 | D6: =0.1*Sheet1!$B6 -> 457.83034 | E6: =Sheet1!$C6-Sheet1!$D6 -> 2180.1445 | F6: =Sheet1!$B6-Sheet1!$E6 -> 2398.1589
A7: 5 | B7: =F6 -> 2398.1589 | C7: =$K$5 -> 2637.9748 | D7: =0.1*Sheet1!$B7 -> 239.81589 | E7: =Sheet1!$C7-Sheet1!$D7 -> 2398.1589 | F7: =Sheet1!$B7-Sheet1!$E7 -> 0
B8: =F7 -> 0 | C8: =SUBTOTAL(9,C3:C7) -> 13189.874 | D8: =SUBTOTAL(9,D3:D7) -> 3189.874 | E8: =SUBTOTAL(109,E3:E7) -> 10000

Sheet Balance_Comparison
A1: Input | B1: Amount | E1: Period (k) | F1: Opening Balance | G1: Installment (R) | H1: Interest (I) | I1: Principal Repaid (P) | J1: Closing Balance
A2: Loan Amount | B2: 2000 | E2: 0 | F2: 0 | G2: 0 | H2: 0 | I2: 0 | J2: =Table3[[#This Row],[Amount]] -> 2000
A3: Annual Rate (j12) | B3: 0.12 | E3: 1 | F3: =J2 -> 2000 | G3: =$B$7 -> 121.9641 | H3: =F3*$B$4 -> 20 | I3: =G3-H3 -> 101.9641 | J3: =F3-I3 -> 1898.0359
A4: Monthly Rate (i) | B4: =B3/12 -> 0.01 | E4: 2 | F4: =J3 -> 1898.0359 | G4: =$B$7 -> 121.9641 | H4: =F4*$B$4 -> 18.980359 | I4: =G4-H4 -> 102.98374 | J4: =F4-I4 -> 1795.0522
A5: Total Months (n) | B5: 18 | E5: 3 | F5: =J4 -> 1795.0522 | G5: =$B$7 -> 121.9641 | H5: =F5*$B$4 -> 17.950522 | I5: =G5-H5 -> 104.01357 | J5: =F5-I5 -> 1691.0386
A6: Period to Check (k) | B6: 8 | E6: 4 | F6: =J5 -> 1691.0386 | G6: =$B$7 -> 121.9641 | H6: =F6*$B$4 -> 16.910386 | I6: =G6-H6 -> 105.05371 | J6: =F6-I6 -> 1585.9849
A7: Monthly Installment | B7: =PMT(B4,B5,-B2) -> 121.9641 | E7: 5 | F7: =J6 -> 1585.9849 | G7: =$B$7 -> 121.9641 | H7: =F7*$B$4 -> 15.859849 | I7: =G7-H7 -> 106.10425 | J7: =F7-I7 -> 1479.8806
E8: 6 | F8: =J7 -> 1479.8806 | G8: =$B$7 -> 121.9641 | H8: =F8*$B$4 -> 14.798806 | I8: =G8-H8 -> 107.16529 | J8: =F8-I8 -> 1372.7153
E9: 7 | F9: =J8 -> 1372.7153 | G9: =$B$7 -> 121.9641 | H9: =F9*$B$4 -> 13.727153 | I9: =G9-H9 -> 108.23694 | J9: =F9-I9 -> 1264.4784
A10: Method | B10: Amount | E10: 8 | F10: =J9 -> 1264.4784 | G10: =$B$7 -> 121.9641 | H10: =F10*$B$4 -> 12.644784 | I10: =G10-H10 -> 109.31931 | J10: =F10-I10 -> 1155.1591
A11: Prospective | B11: =PV(B4,B5-B6,-B7) -> 1155.1591 | E11: 9 | F11: =J10 -> 1155.1591 | G11: =$B$7 -> 121.9641 | H11: =F11*$B$4 -> 11.551591 | I11: =G11-H11 -> 110.4125 | J11: =F11-I11 -> 1044.7466
A12: Retrospective | B12: =(B2*(1+B4)^B6)-FV(B4,B6,-B7) -> 1155.1591 | E12: 10 | F12: =J11 -> 1044.7466 | G12: =$B$7 -> 121.9641 | H12: =F12*$B$4 -> 10.447466 | I12: =G12-H12 -> 111.51663 | J12: =F12-I12 -> 933.22996
E13: 11 | F13: =J12 -> 933.22996 | G13: =$B$7 -> 121.9641 | H13: =F13*$B$4 -> 9.3322996 | I13: =G13-H13 -> 112.6318 | J13: =F13-I13 -> 820.59816
E14: 12 | F14: =J13 -> 820.59816 | G14: =$B$7 -> 121.9641 | H14: =F14*$B$4 -> 8.2059816 | I14: =G14-H14 -> 113.75811 | J14: =F14-I14 -> 706.84005
E15: 13 | F15: =J14 -> 706.84005 | G15: =$B$7 -> 121.9641 | H15: =F15*$B$4 -> 7.0684005 | I15: =G15-H15 -> 114.8957 | J15: =F15-I15 -> 591.94435
E16: 14 | F16: =J15 -> 591.94435 | G16: =$B$7 -> 121.9641 | H16: =F16*$B$4 -> 5.9194435 | I16: =G16-H16 -> 116.04465 | J16: =F16-I16 -> 475.8997
E17: 15 | F17: =J16 -> 475.8997 | G17: =$B$7 -> 121.9641 | H17: =F17*$B$4 -> 4.758997 | I17: =G17-H17 -> 117.2051 | J17: =F17-I17 -> 358.6946
E18: 16 | F18: =J17 -> 358.6946 | G18: =$B$7 -> 121.9641 | H18: =F18*$B$4 -> 3.586946 | I18: =G18-H18 -> 118.37715 | J18: =F18-I18 -> 240.31745
E19: 17 | F19: =J18 -> 240.31745 | G19: =$B$7 -> 121.9641 | H19: =F19*$B$4 -> 2.4031745 | I19: =G19-H19 -> 119.56092 | J19: =F19-I19 -> 120.75653
B20: =Balance_Comparison!B1 -> Amount | E20: 18 | F20: =J19 -> 120.75653 | G20: =$B$7 -> 121.9641 | H20: =F20*$B$4 -> 1.2075653 | I20: =G20-H20 -> 120.75653 | J20: =F20-I20 -> 0

Sheet Student_Balance_Comparison
A1: Input | B1: Amount | F1: Period | G1: opening balance | H1: monthly installment | I1: interest | J1: principal paid | K1: closing balance
A2: Loan Amount | B2: 2000 | F2: 0 | K2: =Table327[[#This Row],[Amount]] -> 2000
A3: Annual Rate (j12) | B3: 0.12 | F3: 1 | G3: =K2 -> 2000 | H3: =$B$7 -> 121.9641 | I3: =$B$4*Table28[[#This Row],[opening balance]] -> 20 | J3: =Table28[[#This Row],[monthly installment ]]-Table28[[#This Row],[interest]] -> 101.9641 | K3: =Table28[[#This Row],[opening balance]]-Table28[[#This Row],[principal paid]] -> 1898.0359
A4: Monthly Rate (i) | B4: =B3/12 -> 0.01 | F4: 2 | G4: =K3 -> 1898.0359 | H4: =$B$7 -> 121.9641 | I4: =$B$4*Table28[[#This Row],[opening balance]] -> 18.980359 | J4: =Table28[[#This Row],[monthly installment ]]-Table28[[#This Row],[interest]] -> 102.98374 | K4: =Table28[[#This Row],[opening balance]]-Table28[[#This Row],[principal paid]] -> 1795.0522
A5: Total Months (n) | B5: 18 | F5: 3 | G5: =K4 -> 1795.0522 | H5: =$B$7 -> 121.9641 | I5: =$B$4*Table28[[#This Row],[opening balance]] -> 17.950522 | J5: =Table28[[#This Row],[monthly installment ]]-Table28[[#This Row],[interest]] -> 104.01357 | K5: =Table28[[#This Row],[opening balance]]-Table28[[#This Row],[principal paid]] -> 1691.0386
A6: Period to Check (k) | B6: 8 | F6: 4 | G6: =K5 -> 1691.0386 | H6: =$B$7 -> 121.9641 | I6: =$B$4*Table28[[#This Row],[opening balance]] -> 16.910386 | J6: =Table28[[#This Row],[monthly installment ]]-Table28[[#This Row],[interest]] -> 105.05371 | K6: =Table28[[#This Row],[opening balance]]-Table28[[#This Row],[principal paid]] -> 1585.9849
A7: Monthly Installment | B7: =PMT(B4,B5,-B2) -> 121.9641 | F7: 5 | G7: =K6 -> 1585.9849 | H7: =$B$7 -> 121.9641 | I7: =$B$4*Table28[[#This Row],[opening balance]] -> 15.859849 | J7: =Table28[[#This Row],[monthly installment ]]-Table28[[#This Row],[interest]] -> 106.10425 | K7: =Table28[[#This Row],[opening balance]]-Table28[[#This Row],[principal paid]] -> 1479.8806
F8: 6 | G8: =K7 -> 1479.8806 | H8: =$B$7 -> 121.9641 | I8: =$B$4*Table28[[#This Row],[opening balance]] -> 14.798806 | J8: =Table28[[#This Row],[monthly installment ]]-Table28[[#This Row],[interest]] -> 107.16529 | K8: =Table28[[#This Row],[opening balance]]-Table28[[#This Row],[principal paid]] -> 1372.7153
F9: 7 | G9: =K8 -> 1372.7153 | H9: =$B$7 -> 121.9641 | I9: =$B$4*Table28[[#This Row],[opening balance]] -> 13.727153 | J9: =Table28[[#This Row],[monthly installment ]]-Table28[[#This Row],[interest]] -> 108.23694 | K9: =Table28[[#This Row],[opening balance]]-Table28[[#This Row],[principal paid]] -> 1264.4784
F10: 8 | G10: =K9 -> 1264.4784 | H10: =$B$7 -> 121.9641 | I10: =$B$4*Table28[[#This Row],[opening balance]] -> 12.644784 | J10: =Table28[[#This Row],[monthly installment ]]-Table28[[#This Row],[interest]] -> 109.31931 | K10: =Table28[[#This Row],[opening balance]]-Table28[[#This Row],[principal paid]] -> 1155.1591
A11: retro | B11: prospective | F11: 9 | G11: =K10 -> 1155.1591 | H11: =$B$7 -> 121.9641 | I11: =$B$4*Table28[[#This Row],[opening balance]] -> 11.551591 | J11: =Table28[[#This Row],[monthly installment ]]-Table28[[#This Row],[interest]] -> 110.4125 | K11: =Table28[[#This Row],[opening balance]]-Table28[[#This Row],[principal paid]] -> 1044.7466
F12: 10 | G12: =K11 -> 1044.7466 | H12: =$B$7 -> 121.9641 | I12: =$B$4*Table28[[#This Row],[opening balance]] -> 10.447466 | J12: =Table28[[#This Row],[monthly installment ]]-Table28[[#This Row],[interest]] -> 111.51663 | K12: =Table28[[#This Row],[opening balance]]-Table28[[#This Row],[principal paid]] -> 933.22996
F13: 11 | G13: =K12 -> 933.22996 | H13: =$B$7 -> 121.9641 | I13: =$B$4*Table28[[#This Row],[opening balance]] -> 9.3322996 | J13: =Table28[[#This Row],[monthly installment ]]-Table28[[#This Row],[interest]] -> 112.6318 | K13: =Table28[[#This Row],[opening balance]]-Table28[[#This Row],[principal paid]] -> 820.59816
F14: 12 | G14: =K13 -> 820.59816 | H14: =$B$7 -> 121.9641 | I14: =$B$4*Table28[[#This Row],[opening balance]] -> 8.2059816 | J14: =Table28[[#This Row],[monthly installment ]]-Table28[[#This Row],[interest]] -> 113.75811 | K14: =Table28[[#This Row],[opening balance]]-Table28[[#This Row],[principal paid]] -> 706.84005
F15: 13 | G15: =K14 -> 706.84005 | H15: =$B$7 -> 121.9641 | I15: =$B$4*Table28[[#This Row],[opening balance]] -> 7.0684005 | J15: =Table28[[#This Row],[monthly installment ]]-Table28[[#This Row],[interest]] -> 114.8957 | K15: =Table28[[#This Row],[opening balance]]-Table28[[#This Row],[principal paid]] -> 591.94435
F16: 14 | G16: =K15 -> 591.94435 | H16: =$B$7 -> 121.9641 | I16: =$B$4*Table28[[#This Row],[opening balance]] -> 5.9194435 | J16: =Table28[[#This Row],[monthly installment ]]-Table28[[#This Row],[interest]] -> 116.04465 | K16: =Table28[[#This Row],[opening balance]]-Table28[[#This Row],[principal paid]] -> 475.8997
F17: 15 | G17: =K16 -> 475.8997 | H17: =$B$7 -> 121.9641 | I17: =$B$4*Table28[[#This Row],[opening balance]] -> 4.758997 | J17: =Table28[[#This Row],[monthly installment ]]-Table28[[#This Row],[interest]] -> 117.2051 | K17: =Table28[[#This Row],[opening balance]]-Table28[[#This Row],[principal paid]] -> 358.6946
F18: 16 | G18: =K17 -> 358.6946 | H18: =$B$7 -> 121.9641 | I18: =$B$4*Table28[[#This Row],[opening balance]] -> 3.586946 | J18: =Table28[[#This Row],[monthly installment ]]-Table28[[#This Row],[interest]] -> 118.37715 | K18: =Table28[[#This Row],[opening balance]]-Table28[[#This Row],[principal paid]] -> 240.31745
A19: method | B19: value | F19: 17 | G19: =K18 -> 240.31745 | H19: =$B$7 -> 121.9641 | I19: =$B$4*Table28[[#This Row],[opening balance]] -> 2.4031745 | J19: =Table28[[#This Row],[monthly installment ]]-Table28[[#This Row],[interest]] -> 119.56092 | K19: =Table28[[#This Row],[opening balance]]-Table28[[#This Row],[principal paid]] -> 120.75653
A20: retrospective | F20: 18 | G20: =K19 -> 120.75653 | H20: =$B$7 -> 121.9641 | I20: =$B$4*Table28[[#This Row],[opening balance]] -> 1.2075653 | J20: =Table28[[#This Row],[monthly installment ]]-Table28[[#This Row],[interest]] -> 120.75653 | K20: =Table28[[#This Row],[opening balance]]-Table28[[#This Row],[principal paid]] -> 0
A21: prospective | B21: =PV(B4,B5-B6,-B7) -> 1155.1591

Sheet Variable_Rates
A1: For 0-5 years | B1: Input | C1: Amount | F1: Period | G1: Opening Balance | H1: Installment (R) | I1: Interest (I) | J1: Principal Repaid (P) | K1: Closing Balance
B2: Loan Amount | C2: 100000 | F2: 0 | G2: 0 | H2: 0 | I2: 0 | J2: 0 | K2: =Table8[[#This Row],[Amount]] -> 100000
B3: Annual Rate (j12) | C3: =7.2/100 -> 0.072 | F3: 1 | G3: =K2 -> 100000 | H3: =$C$6 -> 719.58869 | I3: =G3*$C$4 -> 600 | J3: =H3-I3 -> 119.58869 | K3: =G3-J3 -> 99880.411
B4: Monthly Rate (i) | C4: =C3/12 -> 0.006 | F4: =1+F3 -> 2 | G4: =K3 -> 99880.411 | H4: =$C$6 -> 719.58869 | I4: =G4*$C$4 -> 599.28247 | J4: =H4-I4 -> 120.30622 | K4: =G4-J4 -> 99760.105
B5: Total Months (n) | C5: =25*12 -> 300 | F5: =1+F4 -> 3 | G5: =K4 -> 99760.105 | H5: =$C$6 -> 719.58869 | I5: =G5*$C$4 -> 598.56063 | J5: =H5-I5 -> 121.02806 | K5: =G5-J5 -> 99639.077
B6: Monthly Installment | C6: =PMT(C4,C5,-C2) -> 719.58869 | F6: =1+F5 -> 4 | G6: =K5 -> 99639.077 | H6: =$C$6 -> 719.58869 | I6: =G6*$C$4 -> 597.83446 | J6: =H6-I6 -> 121.75423 | K6: =G6-J6 -> 99517.323
B7: Balance at 5 years | C7: =PV(C4,C5-(5*12),-C6) -> 91393.831 | F7: =1+F6 -> 5 | G7: =K6 -> 99517.323 | H7: =$C$6 -> 719.58869 | I7: =G7*$C$4 -> 597.10394 | J7: =H7-I7 -> 122.48475 | K7: =G7-J7 -> 99394.838
F8: =1+F7 -> 6 | G8: =K7 -> 99394.838 | H8: =$C$6 -> 719.58869 | I8: =G8*$C$4 -> 596.36903 | J8: =H8-I8 -> 123.21966 | K8: =G8-J8 -> 99271.618
F9: =1+F8 -> 7 | G9: =K8 -> 99271.618 | H9: =$C$6 -> 719.58869 | I9: =G9*$C$4 -> 595.62971 | J9: =H9-I9 -> 123.95898 | K9: =G9-J9 -> 99147.659
A10: For 5-25 years | B10: Input | C10: Amount | F10: =1+F9 -> 8 | G10: =K9 -> 99147.659 | H10: =$C$6 -> 719.58869 | I10: =G10*$C$4 -> 594.88596 | J10: =H10-I10 -> 124.70274 | K10: =G10-J10 -> 99022.957
B11: Loan Amount | C11: =C7 -> 91393.831 | F11: =1+F10 -> 9 | G11: =K10 -> 99022.957 | H11: =$C$6 -> 719.58869 | I11: =G11*$C$4 -> 594.13774 | J11: =H11-I11 -> 125.45095 | K11: =G11-J11 -> 98897.506
B12: Annual Rate (j12) | C12: =9/100 -> 0.09 | F12: =1+F11 -> 10 | G12: =K11 -> 98897.506 | H12: =$C$6 -> 719.58869 | I12: =G12*$C$4 -> 593.38503 | J12: =H12-I12 -> 126.20366 | K12: =G12-J12 -> 98771.302
B13: Monthly Rate (i) | C13: =C12/12 -> 0.0075 | F13: =1+F12 -> 11 | G13: =K12 -> 98771.302 | H13: =$C$6 -> 719.58869 | I13: =G13*$C$4 -> 592.62781 | J13: =H13-I13 -> 126.96088 | K13: =G13-J13 -> 98644.341
B14: Total Months (n) | C14: =20*12 -> 240 | F14: =1+F13 -> 12 | G14: =K13 -> 98644.341 | H14: =$C$6 -> 719.58869 | I14: =G14*$C$4 -> 591.86605 | J14: =H14-I14 -> 127.72264 | K14: =G14-J14 -> 98516.619
B15: Monthly Installment | C15: =PMT(C13,C14,-C11) -> 822.29402 | F15: =1+F14 -> 13 | G15: =K14 -> 98516.619 | H15: =$C$6 -> 719.58869 | I15: =G15*$C$4 -> 591.09971 | J15: =H15-I15 -> 128.48898 | K15: =G15-J15 -> 98388.13
F16: =1+F15 -> 14 | G16: =K15 -> 98388.13 | H16: =$C$6 -> 719.58869 | I16: =G16*$C$4 -> 590.32878 | J16: =H16-I16 -> 129.25991 | K16: =G16-J16 -> 98258.87
F17: =1+F16 -> 15 | G17: =K16 -> 98258.87 | H17: =$C$6 -> 719.58869 | I17: =G17*$C$4 -> 589.55322 | J17: =H17-I17 -> 130.03547 | K17: =G17-J17 -> 98128.834
F18: =1+F17 -> 16 | G18: =K17 -> 98128.834 | H18: =$C$6 -> 719.58869 | I18: =G18*$C$4 -> 588.773 | J18: =H18-I18 -> 130.81569 | K18: =G18-J18 -> 97998.018
F19: =1+F18 -> 17 | G19: =K18 -> 97998.018 | H19: =$C$6 -> 719.58869 | I19: =G19*$C$4 -> 587.98811 | J19: =H19-I19 -> 131.60058 | K19: =G19-J19 -> 97866.418
F20: =1+F19 -> 18 | G20: =K19 -> 97866.418 | H20: =$C$6 -> 719.58869 | I20: =G20*$C$4 -> 587.19851 | J20: =H20-I20 -> 132.39018 | K20: =G20-J20 -> 97734.028
F21: =1+F20 -> 19 | G21: =K20 -> 97734.028 | H21: =$C$6 -> 719.58869 | I21: =G21*$C$4 -> 586.40417 | J21: =H21-I21 -> 133.18453 | K21: =G21-J21 -> 97600.843
F22: =1+F21 -> 20 | G22: =K21 -> 97600.843 | H22: =$C$6 -> 719.58869 | I22: =G22*$C$4 -> 585.60506 | J22: =H22-I22 -> 133.98363 | K22: =G22-J22 -> 97466.86
F23: =1+F22 -> 21 | G23: =K22 -> 97466.86 | H23: =$C$6 -> 719.58869 | I23: =G23*$C$4 -> 584.80116 | J23: =H23-I23 -> 134.78753 | K23: =G23-J23 -> 97332.072 | N23: Answer
F24: =1+F23 -> 22 | G24: =K23 -> 97332.072 | H24: =$C$6 -> 719.58869 | I24: =G24*$C$4 -> 583.99243 | J24: =H24-I24 -> 135.59626 | K24: =G24-J24 -> 97196.476 | N24: a. | O24: =C6 -> 719.58869
F25: =1+F24 -> 23 | G25: =K24 -> 97196.476 | H25: =$C$6 -> 719.58869 | I25: =G25*$C$4 -> 583.17885 | J25: =H25-I25 -> 136.40984 | K25: =G25-J25 -> 97060.066 | N25: b. | O25: =C7 -> 91393.831 | P25: =K62 -> 91393.831
F26: =1+F25 -> 24 | G26: =K25 -> 97060.066 | H26: =$C$6 -> 719.58869 | I26: =G26*$C$4 -> 582.3604 | J26: =H26-I26 -> 137.2283 | K26: =G26-J26 -> 96922.838 | N26: c. | O26: =C15-C6 -> 102.70533
F27: =1+F26 -> 25 | G27: =K26 -> 96922.838 | H27: =$C$6 -> 719.58869 | I27: =G27*$C$4 -> 581.53703 | J27: =H27-I27 -> 138.05167 | K27: =G27-J27 -> 96784.786
F28: =1+F27 -> 26 | G28: =K27 -> 96784.786 | H28: =$C$6 -> 719.58869 | I28: =G28*$C$4 -> 580.70872 | J28: =H28-I28 -> 138.87998 | K28: =G28-J28 -> 96645.906
F29: =1+F28 -> 27 | G29: =K28 -> 96645.906 | H29: =$C$6 -> 719.58869 | I29: =G29*$C$4 -> 579.87544 | J29: =H29-I29 -> 139.71326 | K29: =G29-J29 -> 96506.193
F30: =1+F29 -> 28 | G30: =K29 -> 96506.193 | H30: =$C$6 -> 719.58869 | I30: =G30*$C$4 -> 579.03716 | J30: =H30-I30 -> 140.55154 | K30: =G30-J30 -> 96365.641
F31: =1+F30 -> 29 | G31: =K30 -> 96365.641 | H31: =$C$6 -> 719.58869 | I31: =G31*$C$4 -> 578.19385 | J31: =H31-I31 -> 141.39484 | K31: =G31-J31 -> 96224.246
F32: =1+F31 -> 30 | G32: =K31 -> 96224.246 | H32: =$C$6 -> 719.58869 | I32: =G32*$C$4 -> 577.34548 | J32: =H32-I32 -> 142.24321 | K32: =G32-J32 -> 96082.003
F33: =1+F32 -> 31 | G33: =K32 -> 96082.003 | H33: =$C$6 -> 719.58869 | I33: =G33*$C$4 -> 576.49202 | J33: =H33-I33 -> 143.09667 | K33: =G33-J33 -> 95938.906
F34: =1+F33 -> 32 | G34: =K33 -> 95938.906 | H34: =$C$6 -> 719.58869 | I34: =G34*$C$4 -> 575.63344 | J34: =H34-I34 -> 143.95525 | K34: =G34-J34 -> 95794.951
F35: =1+F34 -> 33 | G35: =K34 -> 95794.951 | H35: =$C$6 -> 719.58869 | I35: =G35*$C$4 -> 574.76971 | J35: =H35-I35 -> 144.81898 | K35: =G35-J35 -> 95650.132
F36: =1+F35 -> 34 | G36: =K35 -> 95650.132 | H36: =$C$6 -> 719.58869 | I36: =G36*$C$4 -> 573.90079 | J36: =H36-I36 -> 145.6879 | K36: =G36-J36 -> 95504.444
F37: =1+F36 -> 35 | G37: =K36 -> 95504.444 | H37: =$C$6 -> 719.58869 | I37: =G37*$C$4 -> 573.02667 | J37: =H37-I37 -> 146.56203 | K37: =G37-J37 -> 95357.882
F38: =1+F37 -> 36 | G38: =K37 -> 95357.882 | H38: =$C$6 -> 719.58869 | I38: =G38*$C$4 -> 572.14729 | J38: =H38-I38 -> 147.4414 | K38: =G38-J38 -> 95210.441
... F62: =1+F61 -> 60 | G62: =K61 -> 91564.036 | H62: =$C$6 -> 719.58869 | I62: =G62*$C$4 -> 549.38422 | J62: =H62-I62 -> 170.20448 | K62: =G62-J62 -> 91393.831
F63: =1+F62 -> 61 | G63: =K62 -> 91393.831 | H63: =$C$15 -> 822.29402 | I63: =G63*$C$13 -> 685.45374 | J63: =H63-I63 -> 136.84029 | K63: =G63-J63 -> 91256.991
...

Sheet Student_Variable_Rates
A1: For 0-5 years | B1: Input | C1: Amount | G1: period | H1: opening balance | I1: monthly installment | J1: interest | K1: principal paid | L1: closing balance
B2: Loan Amount | C2: 100000 | G2: 0 | K2: =Table32[[#This Row],[monthly installment]]-Table32[[#This Row],[interest]] -> 0 | L2: 100000
B3: Annual Rate (j12) | C3: =7.2/100 -> 0.072 | G3: =1+G2 -> 1 | H3: =L2 -> 100000 | I3: =$C$6 -> 719.58869 | J3: =$C$4*Table32[[#This Row],[opening balance]] -> 600 | K3: =Table32[[#This Row],[monthly installment]]-Table32[[#This Row],[interest]] -> 119.58869 | L3: =Table32[[#This Row],[opening balance]]-Table32[[#This Row],[principal paid]] -> 99880.411
B4: Monthly Rate (i) | C4: =C3/12 -> 0.006 | G4: =1+G3 -> 2 | H4: =L3 -> 99880.411 | I4: =$C$6 -> 719.58869 | J4: =$C$4*Table32[[#This Row],[opening balance]] -> 599.28247 | K4: =Table32[[#This Row],[monthly installment]]-Table32[[#This Row],[interest]] -> 120.30622 | L4: =Table32[[#This Row],[opening balance]]-Table32[[#This Row],[principal paid]] -> 99760.105
B5: Total Months (n) | C5: =25*12 -> 300 | G5: =1+G4 -> 3 | H5: =L4 -> 99760.105 | I5: =$C$6 -> 719.58869 | J5: =$C$4*Table32[[#This Row],[opening balance]] -> 598.56063 | K5: =Table32[[#This Row],[monthly installment]]-Table32[[#This Row],[interest]] -> 121.02806 | L5: =Table32[[#This Row],[opening balance]]-Table32[[#This Row],[principal paid]] -> 99639.077
B6: Monthly Installment | C6: =PMT(C4,C5,-C2) -> 719.58869 | G6: =1+G5 -> 4 | H6: =L5 -> 99639.077 | I6: =$C$6 -> 719.58869 | J6: =$C$4*Table32[[#This Row],[opening balance]] -> 597.83446 | K6: =Table32[[#This Row],[monthly installment]]-Table32[[#This Row],[interest]] -> 121.75423 | L6: =Table32[[#This Row],[opening balance]]-Table32[[#This Row],[principal paid]] -> 99517.323
B7: Balance at 5 years | C7: =PV(C4,C5-(5*12),-C6) -> 91393.831 | E7: =5*12 -> 60 | G7: =1+G6 -> 5 | H7: =L6 -> 99517.323 | I7: =$C$6 -> 719.58869 | J7: =$C$4*Table32[[#This Row],[opening balance]] -> 597.10394 | K7: =Table32[[#This Row],[monthly installment]]-Table32[[#This Row],[interest]] -> 122.48475 | L7: =Table32[[#This Row],[opening balance]]-Table32[[#This Row],[principal paid]] -> 99394.838
G8: =1+G7 -> 6 | H8: =L7 -> 99394.838 | I8: =$C$6 -> 719.58869 | J8: =$C$4*Table32[[#This Row],[opening balance]] -> 596.36903 | K8: =Table32[[#This Row],[monthly installment]]-Table32[[#This Row],[interest]] -> 123.21966 | L8: =Table32[[#This Row],[opening balance]]-Table32[[#This Row],[principal paid]] -> 99271.618
A9: For 5-25 years | B9: Input | C9: Amount | G9: =1+G8 -> 7 | H9: =L8 -> 99271.618 | I9: =$C$6 -> 719.58869 | J9: =$C$4*Table32[[#This Row],[opening balance]] -> 595.62971 | K9: =Table32[[#This Row],[monthly installment]]-Table32[[#This Row],[interest]] -> 123.95898 | L9: =Table32[[#This Row],[opening balance]]-Table32[[#This Row],[principal paid]] -> 99147.659
B10: Loan Amount | C10: =C7 -> 91393.831 | G10: =1+G9 -> 8 | H10: =L9 -> 99147.659 | I10: =$C$6 -> 719.58869 | J10: =$C$4*Table32[[#This Row],[opening balance]] -> 594.88596 | K10: =Table32[[#This Row],[monthly installment]]-Table32[[#This Row],[interest]] -> 124.70274 | L10: =Table32[[#This Row],[opening balance]]-Table32[[#This Row],[principal paid]] -> 99022.957
B11: Annual Rate (j12) | C11: =9/100 -> 0.09 | G11: =1+G10 -> 9 | H11: =L10 -> 99022.957 | I11: =$C$6 -> 719.58869 | J11: =$C$4*Table32[[#This Row],[opening balance]] -> 594.13774 | K11: =Table32[[#This Row],[monthly installment]]-Table32[[#This Row],[interest]] -> 125.45095 | L11: =Table32[[#This Row],[opening balance]]-Table32[[#This Row],[principal paid]] -> 98897.506
B12: Monthly Rate (i) | C12: =C11/12 -> 0.0075 | G12: =1+G11 -> 10 | H12: =L11 -> 98897.506 | I12: =$C$6 -> 719.58869 | J12: =$C$4*Table32[[#This Row],[opening balance]] -> 593.38503 | K12: =Table32[[#This Row],[monthly installment]]-Table32[[#This Row],[interest]] -> 126.20366 | L12: =Table32[[#This Row],[opening balance]]-Table32[[#This Row],[principal paid]] -> 98771.302
B13: Total Months (n) | C13: =20*12 -> 240 | G13: =1+G12 -> 11 | H13: =L12 -> 98771.302 | I13: =$C$6 -> 719.58869 | J13: =$C$4*Table32[[#This Row],[opening balance]] -> 592.62781 | K13: =Table32[[#This Row],[monthly installment]]-Table32[[#This Row],[interest]] -> 126.96088 | L13: =Table32[[#This Row],[opening balance]]-Table32[[#This Row],[principal paid]] -> 98644.341
B14: Monthly Installment | C14: =PMT(C12,Student_Variable_Rates!C13,-Student_Variable_Rates!C10) -> 822.29402 | G14: =1+G13 -> 12 | H14: =L13 -> 98644.341 | I14: =$C$6 -> 719.58869 | J14: =$C$4*Table32[[#This Row],[opening balance]] -> 591.86605 | K14: =Table32[[#This Row],[monthly installment]]-Table32[[#This Row],[interest]] -> 127.72264 | L14: =Table32[[#This Row],[opening balance]]-Table32[[#This Row],[principal paid]] -> 98516.619
G15: =1+G14 -> 13 | H15: =L14 -> 98516.619 | I15: =$C$6 -> 719.58869 | J15: =$C$4*Table32[[#This Row],[opening balance]] -> 591.09971 | K15: =Table32[[#This Row],[monthly installment]]-Table32[[#This Row],[interest]] -> 128.48898 | L15: =Table32[[#This Row],[opening balance]]-Table32[[#This Row],[principal paid]] -> 98388.13
G16: =1+G15 -> 14 | H16: =L15 -> 98388.13 | I16: =$C$6 -> 719.58869 | J16: =$C$4*Table32[[#This Row],[opening balance]] -> 590.32878 | K16: =Table32[[#This Row],[monthly installment]]-Table32[[#This Row],[interest]] -> 129.25991 | L16: =Table32[[#This Row],[opening balance]]-Table32[[#This Row],[principal paid]] -> 98258.87
G17: =1+G16 -> 15 | H17: =L16 -> 98258.87 | I17: =$C$6 -> 719.58869 | J17: =$C$4*Table32[[#This Row],[opening balance]] -> 589.55322 | K17: =Table32[[#This Row],[monthly installment]]-Table32[[#This Row],[interest]] -> 130.03547 | L17: =Table32[[#This Row],[opening balance]]-Table32[[#This Row],[principal paid]] -> 98128.834
G18: =1+G17 -> 16 | H18: =L17 -> 98128.834 | I18: =$C$6 -> 719.58869 | J18: =$C$4*Table32[[#This Row],[opening balance]] -> 588.773 | K18: =Table32[[#This Row],[monthly installment]]-Table32[[#This Row],[interest]] -> 130.81569 | L18: =Table32[[#This Row],[opening balance]]-Table32[[#This Row],[principal paid]] -> 97998.018
G19: =1+G18 -> 17 | H19: =L18 -> 97998.018 | I19: =$C$6 -> 719.58869 | J19: =$C$4*Table32[[#This Row],[opening balance]] -> 587.98811 | K19: =Table32[[#This Row],[monthly installment]]-Table32[[#This Row],[interest]] -> 131.60058 | L19: =Table32[[#This Row],[opening balance]]-Table32[[#This Row],[principal paid]] -> 97866.418
G20: =1+G19 -> 18 | H20: =L19 -> 97866.418 | I20: =$C$6 -> 719.58869 | J20: =$C$4*Table32[[#This Row],[opening balance]] -> 587.19851 | K20: =Table32[[#This Row],[monthly installment]]-Table32[[#This Row],[interest]] -> 132.39018 | L20: =Table32[[#This Row],[opening balance]]-Table32[[#This Row],[principal paid]] -> 97734.028
G21: =1+G20 -> 19 | H21: =L20 -> 97734.028 | I21: =$C$6 -> 719.58869 | J21: =$C$4*Table32[[#This Row],[opening balance]] -> 586.40417 | K21: =Table32[[#This Row],[monthly installment]]-Table32[[#This Row],[interest]] -> 133.18453 | L21: =Table32[[#This Row],[opening balance]]-Table32[[#This Row],[principal paid]] -> 97600.843
G22: =1+G21 -> 20 | H22: =L21 -> 97600.843 | I22: =$C$6 -> 719.58869 | J22: =$C$4*Table32[[#This Row],[opening balance]] -> 585.60506 | K22: =Table32[[#This Row],[monthly installment]]-Table32[[#This Row],[interest]] -> 133.98363 | L22: =Table32[[#This Row],[opening balance]]-Table32[[#This Row],[principal paid]] -> 97466.86
G23: =1+G22 -> 21 | H23: =L22 -> 97466.86 | I23: =$C$6 -> 719.58869 | J23: =$C$4*Table32[[#This Row],[opening balance]] -> 584.80116 | K23: =Table32[[#This Row],[monthly installment]]-Table32[[#This Row],[interest]] -> 134.78753 | L23: =Table32[[#This Row],[opening balance]]-Table32[[#This Row],[principal paid]] -> 97332.072
G24: =1+G23 -> 22 | H24: =L23 -> 97332.072 | I24: =$C$6 -> 719.58869 | J24: =$C$4*Table32[[#This Row],[opening balance]] -> 583.99243 | K24: =Table32[[#This Row],[monthly installment]]-Table32[[#This Row],[interest]] -> 135.59626 | L24: =Table32[[#This Row],[opening balance]]-Table32[[#This Row],[principal paid]] -> 97196.476
G25: =1+G24 -> 23 | H25: =L24 -> 97196.476 | I25: =$C$6 -> 719.58869 | J25: =$C$4*Table32[[#This Row],[opening balance]] -> 583.17885 | K25: =Table32[[#This Row],[monthly installment]]-Table32[[#This Row],[interest]] -> 136.40984 | L25: =Table32[[#This Row],[opening balance]]-Table32[[#This Row],[principal paid]] -> 97060.066
G26: =1+G25 -> 24 | H26: =L25 -> 97060.066 | I26: =$C$6 -> 719.58869 | J26: =$C$4*Table32[[#This Row],[opening balance]] -> 582.3604 | K26: =Table32[[#This Row],[monthly installment]]-Table32[[#This Row],[interest]] -> 137.2283 | L26: =Table32[[#This Row],[opening balance]]-Table32[[#This Row],[principal paid]] -> 96922.838
... G62: =1+G61 -> 60 | H62: =L61 -> 91564.036 | I62: =$C$6 -> 719.58869 | J62: =$C$4*Table32[[#This Row],[opening balance]] -> 549.38422 | K62: =Table32[[#This Row],[monthly installment]]-Table32[[#This Row],[interest]] -> 170.20448 | L62: =Table32[[#This Row],[opening balance]]-Table32[[#This Row],[principal paid]] -> 91393.831
G63: =1+G62 -> 61 | H63: =L62 -> 91393.831 | I63: =$C$14 -> 822.29402 | J63: =$C$12*Table32[[#This Row],[opening balance]] -> 685.45374 | K63: =Table32[[#This Row],[monthly installment]]-Table32[[#This Row],[interest]] -> 136.84029 | L63: =Table32[[#This Row],[opening balance]]-Table32[[#This Row],[principal paid]] -> 91256.991
G64: =1+G63 -> 62 | H64: =L63 -> 91256.991 | I64: =$C$14 -> 822.29402 | J64: =$C$12*Table32[[#This Row],[opening balance]] -> 684.42743 | K64: =Table32[[#This Row],[monthly installment]]-Table32[[#This Row],[interest]] -> 137.86659 | L64: =Table32[[#This Row],[opening balance]]-Table32[[#This Row],[principal paid]] -> 91119.125
G65: =1+G64 -> 63 | H65: =L64 -> 91119.125 | I65: =$C$14 -> 822.29402 | J65: =$C$12*Table32[[#This Row],[opening balance]] -> 683.39343 | K65: =Table32[[#This Row],[monthly installment]]-Table32[[#This Row],[interest]] -> 138.90059 | L65: =Table32[[#This Row],[opening balance]]-Table32[[#This Row],[principal paid]] -> 90980.224
G66: =1+G65 -> 64 | H66: =L65 -> 90980.224 | I66: =$C$14 -> 822.29402 | J66: =$C$12*Table32[[#This Row],[opening balance]] -> 682.35168 | K66: =Table32[[#This Row],[monthly installment]]-Table32[[#This Row],[interest]] -> 139.94234 | L66: =Table32[[#This Row],[opening balance]]-Table32[[#This Row],[principal paid]] -> 90840.282
G67: =1+G66 -> 65 | H67: =L66 -> 90840.282 | I67: =$C$14 -> 822.29402 | J67: =$C$12*Table32[[#This Row],[opening balance]] -> 681.30211 | K67: =Table32[[#This Row],[monthly installment]]-Table32[[#This Row],[interest]] -> 140.99191 | L67: =Table32[[#This Row],[opening balance]]-Table32[[#This Row],[principal paid]] -> 90699.29
G68: =1+G67 -> 66 | H68: =L67 -> 90699.29 | I68: =$C$14 -> 822.29402 | J68: =$C$12*Table32[[#This Row],[opening balance]] -> 680.24467 | K68: =Table32[[#This Row],[monthly installment]]-Table32[[#This Row],[interest]] -> 142.04935 | L68: =Table32[[#This Row],[opening balance]]-Table32[[#This Row],[principal paid]] -> 90557.24
G69: =1+G68 -> 67 | H69: =L68 -> 90557.24 | I69: =$C$14 -> 822.29402 | J69: =$C$12*Table32[[#This Row],[opening balance]] -> 679.1793 | K69: =Table32[[#This Row],[monthly installment]]-Table32[[#This Row],[interest]] -> 143.11472 | L69: =Table32[[#This Row],[opening balance]]-Table32[[#This Row],[principal paid]] -> 90414.126
G70: =1+G69 -> 68 | H70: =L69 -> 90414.126 | I70: =$C$14 -> 822.29402 | J70: =$C$12*Table32[[#This Row],[opening balance]] -> 678.10594 | K70: =Table32[[#This Row],[monthly installment]]-Table32[[#This Row],[interest]] -> 144.18808 | L70: =Table32[[#This Row],[opening balance]]-Table32[[#This Row],[principal paid]] -> 90269.938
G71: =1+G70 -> 69 | H71: =L70 -> 90269.938 | I71: =$C$14 -> 822.29402 | J71: =$C$12*Table32[[#This Row],[opening balance]] -> 677.02453 | K71: =Table32[[#This Row],[monthly installment]]-Table32[[#This Row],[interest]] -> 145.26949 | L71: =Table32[[#This Row],[opening balance]]-Table32[[#This Row],[principal paid]] -> 90124.668
G72: =1+G71 -> 70 | H72: =L71 -> 90124.668 | I72: =$C$14 -> 822.29402 | J72: =$C$12*Table32[[#This Row],[opening balance]] -> 675.93501 | K72: =Table32[[#This Row],[monthly installment]]-Table32[[#This Row],[interest]] -> 146.35901 | L72: =Table32[[#This Row],[opening balance]]-Table32[[#This Row],[principal paid]] -> 89978.309
G73: =1+G72 -> 71 | H73: =L72 -> 89978.309 | I73: =$C$14 -> 822.29402 | J73: =$C$12*Table32[[#This Row],[opening balance]] -> 674.83732 | K73: =Table32[[#This Row],[monthly installment]]-Table32[[#This Row],[interest]] -> 147.45671 | L73: =Table32[[#This Row],[opening balance]]-Table32[[#This Row],[principal paid]] -> 89830.852
G74: =1+G73 -> 72 | H74: =L73 -> 89830.852 | I74: =$C$14 -> 822.29402 | J74: =$C$12*Table32[[#This Row],[opening balance]] -> 673.73139 | K74: =Table32[[#This Row],[monthly installment]]-Table32[[#This Row],[interest]] -> 148.56263 | L74: =Table32[[#This Row],[opening balance]]-Table32[[#This Row],[principal paid]] -> 89682.29
... G302: =1+G301 -> 300 | H302: =L301 -> 816.17273 | I302: =$C$14 -> 822.29402 | J302: =$C$12*Table32[[#This Row],[opening balance]] -> 6.1212955 | K302: =Table32[[#This Row],[monthly installment]]-Table32[[#This Row],[interest]] -> 816.17273 | L302: =Table32[[#This Row],[opening balance]]-Table32[[#This Row],[principal paid]] -> 2.487468e-10

Sheet Flat_Rate_Rule78
A1: Input | B1: Amount | E1: Period | F1: Unit Interest | G1: Opening Balance | H1: Installment (R) | I1: Interest Due (I) | J1: Principal Repaid (P) | K1: Closing Balance
A2: Loan Amount | B2: 2000 | E2: 0 | F2: 0 | G2: 0 | H2: 0 | I2: 0 | J2: 0 | K2: =B2 -> 2000
A3: Interest(Flat basis) | B3: 0.12 | E3: 1 | F3: =E26 -> 24 | G3: =K2 -> 2000 | H3: =$B$7 -> 103.33333 | I3: =F3*$B$9 -> 38.4 | J3: =H3-I3 -> 64.933333 | K3: =G3-J3 -> 1935.0667
A4: Duration in years | B4: 2 | E4: 2 | F4: =F3-1 -> 23 | G4: =K3 -> 1935.0667 | H4: =$B$7 -> 103.33333 | I4: =F4*$B$9 -> 36.8 | J4: =H4-I4 -> 66.533333 | K4: =G4-J4 -> 1868.5333
A5: Total Months (n) | B5: =B4*12 -> 24 | E5: 3 | F5: =F4-1 -> 22 | G5: =K4 -> 1868.5333 | H5: =$B$7 -> 103.33333 | I5: =F5*$B$9 -> 35.2 | J5: =H5-I5 -> 68.133333 | K5: =G5-J5 -> 1800.4
A6: Loan Interest | B6: =B2*B3*B4 -> 480 | E6: 4 | F6: =F5-1 -> 21 | G6: =K5 -> 1800.4 | H6: =$B$7 -> 103.33333 | I6: =F6*$B$9 -> 33.6 | J6: =H6-I6 -> 69.733333 | K6: =G6-J6 -> 1730.6667
A7: Monthly Installment | B7: =(B2+B6)/B5 -> 103.33333 | E7: 5 | F7: =F6-1 -> 20 | G7: =K6 -> 1730.6667 | H7: =$B$7 -> 103.33333 | I7: =F7*$B$9 -> 32 | J7: =H7-I7 -> 71.333333 | K7: =G7-J7 -> 1659.3333
A8: Number of unit interest | B8: =B5/2*(1+B5) -> 300 | E8: 6 | F8: =F7-1 -> 19 | G8: =K7 -> 1659.3333 | H8: =$B$7 -> 103.33333 | I8: =F8*$B$9 -> 30.4 | J8: =H8-I8 -> 72.933333 | K8: =G8-J8 -> 1586.4
A9: Value of unit of interest | B9: =B6/B8 -> 1.6 | E9: 7 | F9: =F8-1 -> 18 | G9: =K8 -> 1586.4 | H9: =$B$7 -> 103.33333 | I9: =F9*$B$9 -> 28.8 | J9: =H9-I9 -> 74.533333 | K9: =G9-J9 -> 1511.8667
E10: 8 | F10: =F9-1 -> 17 | G10: =K9 -> 1511.8667 | H10: =$B$7 -> 103.33333 | I10: =F10*$B$9 -> 27.2 | J10: =H10-I10 -> 76.133333 | K10: =G10-J10 -> 1435.7333
E11: 9 | F11: =F10-1 -> 16 | G11: =K10 -> 1435.7333 | H11: =$B$7 -> 103.33333 | I11: =F11*$B$9 -> 25.6 | J11: =H11-I11 -> 77.733333 | K11: =G11-J11 -> 1358
E12: 10 | F12: =F11-1 -> 15 | G12: =K11 -> 1358 | H12: =$B$7 -> 103.33333 | I12: =F12*$B$9 -> 24 | J12: =H12-I12 -> 79.333333 | K12: =G12-J12 -> 1278.6667
E13: 11 | F13: =F12-1 -> 14 | G13: =K12 -> 1278.6667 | H13: =$B$7 -> 103.33333 | I13: =F13*$B$9 -> 22.4 | J13: =H13-I13 -> 80.933333 | K13: =G13-J13 -> 1197.7333
E14: 12 | F14: =F13-1 -> 13 | G14: =K13 -> 1197.7333 | H14: =$B$7 -> 103.33333 | I14: =F14*$B$9 -> 20.8 | J14: =H14-I14 -> 82.533333 | K14: =G14-J14 -> 1115.2
E15: 13 | F15: =F14-1 -> 12 | G15: =K14 -> 1115.2 | H15: =$B$7 -> 103.33333 | I15: =F15*$B$9 -> 19.2 | J15: =H15-I15 -> 84.133333 | K15: =G15-J15 -> 1031.0667
E16: 14 | F16: =F15-1 -> 11 | G16: =K15 -> 1031.0667 | H16: =$B$7 -> 103.33333 | I16: =F16*$B$9 -> 17.6 | J16: =H16-I16 -> 85.733333 | K16: =G16-J16 -> 945.33333
E17: 15 | F17: =F16-1 -> 10 | G17: =K16 -> 945.33333 | H17: =$B$7 -> 103.33333 | I17: =F17*$B$9 -> 16 | J17: =H17-I17 -> 87.333333 | K17: =G17-J17 -> 858
E18: 16 | F18: =F17-1 -> 9 | G18: =K17 -> 858 | H18: =$B$7 -> 103.33333 | I18: =F18*$B$9 -> 14.4 | J18: =H18-I18 -> 88.933333 | K18: =G18-J18 -> 769.06667
E19: 17 | F19: =F18-1 -> 8 | G19: =K18 -> 769.06667 | H19: =$B$7 -> 103.33333 | I19: =F19*$B$9 -> 12.8 | J19: =H19-I19 -> 90.533333 | K19: =G19-J19 -> 678.53333
E20: 18 | F20: =F19-1 -> 7 | G20: =K19 -> 678.53333 | H20: =$B$7 -> 103.33333 | I20: =F20*$B$9 -> 11.2 | J20: =H20-I20 -> 92.133333 | K20: =G20-J20 -> 586.4
E21: 19 | F21: =F20-1 -> 6 | G21: =K20 -> 586.4 | H21: =$B$7 -> 103.33333 | I21: =F21*$B$9 -> 9.6 | J21: =H21-I21 -> 93.733333 | K21: =G21-J21 -> 492.66667
... E26: 24 | F26: =F25-1 -> 1 | G26: =K25 -> 101.73333 | H26: =$B$7 -> 103.33333 | I26: =F26*$B$9 -> 1.6 | J26: =H26-I26 -> 101.73333 | K26: =G26-J26 -> 4.405365e-13

Sheet Student_Flat_Rate_Rule78
A1: Input | B1: Amount | E1: Period | F1: Unit Interest | G1: Opening Balance | H1: Installment (R) | I1: Interest Due (I) | J1: Principal Repaid (P) | K1: Closing Balance
A2: Loan Amount | B2: 2000 | E2: 0 | F2: 0 | G2: 0 | H2: 0 | I2: 0 | J2: 0 | K2: =B2 -> 2000
A3: Interest(Flat basis) | B3: 0.12 | E3: 1 | F3: =B5 -> 24 | G3: =K2 -> 2000 | H3: =$B$7 -> 103.33333 | I3: =F3*$B$9 -> 38.4 | J3: =H3-I3 -> 64.933333 | K3: =G3-J3 -> 1935.0667
A4: Duration in years | B4: 2 | E4: 2 | F4: =F3-1 -> 23 | G4: =K3 -> 1935.0667 | H4: =$B$7 -> 103.33333 | I4: =F4*$B$9 -> 36.8 | J4: =H4-I4 -> 66.533333 | K4: =G4-J4 -> 1868.5333
A5: Total Months (n) | B5: =B4*12 -> 24 | E5: 3 | F5: =F4-1 -> 22 | G5: =K4 -> 1868.5333 | H5: =$B$7 -> 103.33333 | I5: =F5*$B$9 -> 35.2 | J5: =H5-I5 -> 68.133333 | K5: =G5-J5 -> 1800.4
A6: Loan Interest | B6: =B2*B3*B4 -> 480 | E6: 4 | F6: =F5-1 -> 21 | G6: =K5 -> 1800.4 | H6: =$B$7 -> 103.33333 | I6: =F6*$B$9 -> 33.6 | J6: =H6-I6 -> 69.733333 | K6: =G6-J6 -> 1730.6667
A7: Monthly Installment | B7: =(B2+B6)/B5 -> 103.33333 | E7: 5 | F7: =F6-1 -> 20 | G7: =K6 -> 1730.6667 | H7: =$B$7 -> 103.33333 | I7: =F7*$B$9 -> 32 | J7: =H7-I7 -> 71.333333 | K7: =G7-J7 -> 1659.3333
A8: Number of unit interest | B8: =B5/2*(1+B5) -> 300 | E8: 6 | F8: =F7-1 -> 19 | G8: =K7 -> 1659.3333 | H8: =$B$7 -> 103.33333 | I8: =F8*$B$9 -> 30.4 | J8: =H8-I8 -> 72.933333 | K8: =G8-J8 -> 1586.4
A9: Value of unit of interest | B9: =B6/B8 -> 1.6 | E9: 7 | F9: =F8-1 -> 18 | G9: =K8 -> 1586.4 | H9: =$B$7 -> 103.33333 | I9: =F9*$B$9 -> 28.8 | J9: =H9-I9 -> 74.533333 | K9: =G9-J9 -> 1511.8667
E10: 8 | F10: =F9-1 -> 17 | G10: =K9 -> 1511.8667 | H10: =$B$7 -> 103.33333 | I10: =F10*$B$9 -> 27.2 | J10: =H10-I10 -> 76.133333 | K10: =G10-J10 -> 1435.7333
E11: 9 | F11: =F10-1 -> 16 | G11: =K10 -> 1435.7333 | H11: =$B$7 -> 103.33333 | I11: =F11*$B$9 -> 25.6 | J11: =H11-I11 -> 77.733333 | K11: =G11-J11 -> 1358
E12: 10 | F12: =F11-1 -> 15 | G12: =K11 -> 1358 | H12: =$B$7 -> 103.33333 | I12: =F12*$B$9 -> 24 | J12: =H12-I12 -> 79.333333 | K12: =G12-J12 -> 1278.6667
E13: 11 | F13: =F12-1 -> 14 | G13: =K12 -> 1278.6667 | H13: =$B$7 -> 103.33333 | I13: =F13*$B$9 -> 22.4 | J13: =H13-I13 -> 80.933333 | K13: =G13-J13 -> 1197.7333
E14: 12 | F14: =F13-1 -> 13 | G14: =K13 -> 1197.7333 | H14: =$B$7 -> 103.33333 | I14: =F14*$B$9 -> 20.8 | J14: =H14-I14 -> 82.533333 | K14: =G14-J14 -> 1115.2
E15: 13 | F15: =F14-1 -> 12 | G15: =K14 -> 1115.2 | H15: =$B$7 -> 103.33333 | I15: =F15*$B$9 -> 19.2 | J15: =H15-I15 -> 84.133333 | K15: =G15-J15 -> 1031.0667
E16: 14 | F16: =F15-1 -> 11 | G16: =K15 -> 1031.0667 | H16: =$B$7 -> 103.33333 | I16: =F16*$B$9 -> 17.6 | J16: =H16-I16 -> 85.733333 | K16: =G16-J16 -> 945.33333
E17: 15 | F17: =F16-1 -> 10 | G17: =K16 -> 945.33333 | H17: =$B$7 -> 103.33333 | I17: =F17*$B$9 -> 16 | J17: =H17-I17 -> 87.333333 | K17: =G17-J17 -> 858
E18: 16 | F18: =F17-1 -> 9 | G18: =K17 -> 858 | H18: =$B$7 -> 103.33333 | I18: =F18*$B$9 -> 14.4 | J18: =H18-I18 -> 88.933333 | K18: =G18-J18 -> 769.06667
E19: 17 | F19: =F18-1 -> 8 | G19: =K18 -> 769.06667 | H19: =$B$7 -> 103.33333 | I19: =F19*$B$9 -> 12.8 | J19: =H19-I19 -> 90.533333 | K19: =G19-J19 -> 678.53333
E20: 18 | F20: =F19-1 -> 7 | G20: =K19 -> 678.53333 | H20: =$B$7 -> 103.33333 | I20: =F20*$B$9 -> 11.2 | J20: =H20-I20 -> 92.133333 | K20: =G20-J20 -> 586.4
E21: 19 | F21: =F20-1 -> 6 | G21: =K20 -> 586.4 | H21: =$B$7 -> 103.33333 | I21: =F21*$B$9 -> 9.6 | J21: =H21-I21 -> 93.733333 | K21: =G21-J21 -> 492.66667
... E26: 24 | F26: =F25-1 -> 1 | G26: =K25 -> 101.73333 | H26: =$B$7 -> 103.33333 | I26: =F26*$B$9 -> 1.6 | J26: =H26-I26 -> 101.73333 | K26: =G26-J26 -> 4.405365e-13

Sheet Practice_Problems_1
A1: input | B1: amount | D1: period | E1: opening balance | F1: monhly installment | G1: interest | H1: principal paid | I1: closing balance
A2: loan principal | B2: 50000 | D2: 0 | G2: =(6%/12)*Table21[[#This Row],[opening balance]] -> 0 | H2: =Table21[[#This Row],[monhly installment]]-Table21[[#This Row],[interest]] -> 0 | I2: 50000
A3: interest rates | B3: 0.06 | D3: 1 | E3: =I2 -> 50000 | F3: =$B$6 -> 555.10251 | G3: =(6%/12)*Table21[[#This Row],[opening balance]] -> 250 | H3: =Table21[[#This Row],[monhly installment]]-Table21[[#This Row],[interest]] -> 305.10251 | I3: =Table21[[#This Row],[opening balance]]-Table21[[#This Row],[principal paid]] -> 49694.897
A4: n (years) | B4: 10 | D4: =D3+1 -> 2 | E4: =I3 -> 49694.897 | F4: =$B$6 -> 555.10251 | G4: =(6%/12)*Table21[[#This Row],[opening balance]] -> 248.47449 | H4: =Table21[[#This Row],[monhly installment]]-Table21[[#This Row],[interest]] -> 306.62802 | I4: =Table21[[#This Row],[opening balance]]-Table21[[#This Row],[principal paid]] -> 49388.269
A5: n (month) | B5: =B4*12 -> 120 | D5: =D4+1 -> 3 | E5: =I4 -> 49388.269 | F5: =$B$6 -> 555.10251 | G5: =(6%/12)*Table21[[#This Row],[opening balance]] -> 246.94135 | H5: =Table21[[#This Row],[monhly installment]]-Table21[[#This Row],[interest]] -> 308.16116 | I5: =Table21[[#This Row],[opening balance]]-Table21[[#This Row],[principal paid]] -> 49080.108
A6: monthly instalment | B6: =PMT(B3/12,B5,-B2) -> 555.10251 | D6: =D5+1 -> 4 | E6: =I5 -> 49080.108 | F6: =$B$6 -> 555.10251 | G6: =(6%/12)*Table21[[#This Row],[opening balance]] -> 245.40054 | H6: =Table21[[#This Row],[monhly installment]]-Table21[[#This Row],[interest]] -> 309.70197 | I6: =Table21[[#This Row],[opening balance]]-Table21[[#This Row],[principal paid]] -> 48770.406
A7: PV at 36th month | B7: =PV(B3/12,120-36,-B6) - 5000 -> 32998.456 | D7: =D6+1 -> 5 | E7: =I6 -> 48770.406 | F7: =$B$6 -> 555.10251 | G7: =(6%/12)*Table21[[#This Row],[opening balance]] -> 243.85203 | H7: =Table21[[#This Row],[monhly installment]]-Table21[[#This Row],[interest]] -> 311.25048 | I7: =Table21[[#This Row],[opening balance]]-Table21[[#This Row],[principal paid]] -> 48459.156
A8: new n | B8: =NPER(B3/12,-B6,B7) -> 70.720906 | D8: =D7+1 -> 6 | E8: =I7 -> 48459.156 | F8: =$B$6 -> 555.10251 | G8: =(6%/12)*Table21[[#This Row],[opening balance]] -> 242.29578 | H8: =Table21[[#This Row],[monhly installment]]-Table21[[#This Row],[interest]] -> 312.80673 | I8: =Table21[[#This Row],[opening balance]]-Table21[[#This Row],[principal paid]] -> 48146.349
A9: month saved | B9: =B5-36-B8 -> 13.279094 | D9: =D8+1 -> 7 | E9: =I8 -> 48146.349 | F9: =$B$6 -> 555.10251 | G9: =(6%/12)*Table21[[#This Row],[opening balance]] -> 240.73175 | H9: =Table21[[#This Row],[monhly installment]]-Table21[[#This Row],[interest]] -> 314.37076 | I9: =Table21[[#This Row],[opening balance]]-Table21[[#This Row],[principal paid]] -> 47831.978
D10: =D9+1 -> 8 | E10: =I9 -> 47831.978 | F10: =$B$6 -> 555.10251 | G10: =(6%/12)*Table21[[#This Row],[opening balance]] -> 239.15989 | H10: =Table21[[#This Row],[monhly installment]]-Table21[[#This Row],[interest]] -> 315.94262 | I10: =Table21[[#This Row],[opening balance]]-Table21[[#This Row],[principal paid]] -> 47516.036
D11: =D10+1 -> 9 | E11: =I10 -> 47516.036 | F11: =$B$6 -> 555.10251 | G11: =(6%/12)*Table21[[#This Row],[opening balance]] -> 237.58018 | H11: =Table21[[#This Row],[monhly installment]]-Table21[[#This Row],[interest]] -> 317.52233 | I11: =Table21[[#This Row],[opening balance]]-Table21[[#This Row],[principal paid]] -> 47198.513
D12: =D11+1 -> 10 | E12: =I11 -> 47198.513 | F12: =$B$6 -> 555.10251 | G12: =(6%/12)*Table21[[#This Row],[opening balance]] -> 235.99257 | H12: =Table21[[#This Row],[monhly installment]]-Table21[[#This Row],[interest]] -> 319.10994 | I12: =Table21[[#This Row],[opening balance]]-Table21[[#This Row],[principal paid]] -> 46879.403
D13: =D12+1 -> 11 | E13: =I12 -> 46879.403 | F13: =$B$6 -> 555.10251 | G13: =(6%/12)*Table21[[#This Row],[opening balance]] -> 234.39702 | H13: =Table21[[#This Row],[monhly installment]]-Table21[[#This Row],[interest]] -> 320.70549 | I13: =Table21[[#This Row],[opening balance]]-Table21[[#This Row],[principal paid]] -> 46558.698
D14: =D13+1 -> 12 | E14: =I13 -> 46558.698 | F14: =$B$6 -> 555.10251 | G14: =(6%/12)*Table21[[#This Row],[opening balance]] -> 232.79349 | H14: =Table21[[#This Row],[monhly installment]]-Table21[[#This Row],[interest]] -> 322.30902 | I14: =Table21[[#This Row],[opening balance]]-Table21[[#This Row],[principal paid]] -> 46236.389
D15: =D14+1 -> 13 | E15: =I14 -> 46236.389 | F15: =$B$6 -> 555.10251 | G15: =(6%/12)*Table21[[#This Row],[opening balance]] -> 231.18194 | H15: =Table21[[#This Row],[monhly installment]]-Table21[[#This Row],[interest]] -> 323.92056 | I15: =Table21[[#This Row],[opening balance]]-Table21[[#This Row],[principal paid]] -> 45912.468
D16: =D15+1 -> 14 | E16: =I15 -> 45912.468 | F16: =$B$6 -> 555.10251 | G16: =(6%/12)*Table21[[#This Row],[opening balance]] -> 229.56234 | H16: =Table21[[#This Row],[monhly installment]]-Table21[[#This Row],[interest]] -> 325.54017 | I16: =Table21[[#This Row],[opening balance]]-Table21[[#This Row],[principal paid]] -> 45586.928
D17: =D16+1 -> 15 | E17: =I16 -> 45586.928 | F17: =$B$6 -> 555.10251 | G17: =(6%/12)*Table21[[#This Row],[opening balance]] -> 227.93464 | H17: =Table21[[#This Row],[monhly installment]]-Table21[[#This Row],[interest]] -> 327.16787 | I17: =Table21[[#This Row],[opening balance]]-Table21[[#This Row],[principal paid]] -> 45259.76
D18: =D17+1 -> 16 | E18: =I17 -> 45259.76 | F18: =$B$6 -> 555.10251 | G18: =(6%/12)*Table21[[#This Row],[opening balance]] -> 226.2988 | H18: =Table21[[#This Row],[monhly installment]]-Table21[[#This Row],[interest]] -> 328.80371 | I18: =Table21[[#This Row],[opening balance]]-Table21[[#This Row],[principal paid]] -> 44930.957
D19: =D18+1 -> 17 | E19: =I18 -> 44930.957 | F19: =$B$6 -> 555.10251 | G19: =(6%/12)*Table21[[#This Row],[opening balance]] -> 224.65478 | H19: =Table21[[#This Row],[monhly installment]]-Table21[[#This Row],[interest]] -> 330.44773 | I19: =Table21[[#This Row],[opening balance]]-Table21[[#This Row],[principal paid]] -> 44600.509
D20: =D19+1 -> 18 | E20: =I19 -> 44600.509 | F20: =$B$6 -> 555.10251 | G20: =(6%/12)*Table21[[#This Row],[opening balance]] -> 223.00254 | H20: =Table21[[#This Row],[monhly installment]]-Table21[[#This Row],[interest]] -> 332.09997 | I20: =Table21[[#This Row],[opening balance]]-Table21[[#This Row],[principal paid]] -> 44268.409
D21: =D20+1 -> 19 | E21: =I20 -> 44268.409 | F21: =$B$6 -> 555.10251 | G21: =(6%/12)*Table21[[#This Row],[opening balance]] -> 221.34204 | H21: =Table21[[#This Row],[monhly installment]]-Table21[[#This Row],[interest]] -> 333.76046 | I21: =Table21[[#This Row],[opening balance]]-Table21[[#This Row],[principal paid]] -> 43934.648
... D37: =D36+1 -> 35 | E37: =I36 -> 38723.236 | F37: =$B$6 -> 555.10251 | G37: =(6%/12)*Table21[[#This Row],[opening balance]] -> 193.61618 | H37: =Table21[[#This Row],[monhly installment]]-Table21[[#This Row],[interest]] -> 361.48633 | I37: =Table21[[#This Row],[opening balance]]-Table21[[#This Row],[principal paid]] -> 38361.749
D38: =D37+1 -> 36 | E38: =I37 -> 38361.749 | F38: =$B$6 -> 555.10251 | G38: =(6%/12)*Table21[[#This Row],[opening balance]] -> 191.80875 | H38: =Table21[[#This Row],[monhly installment]]-Table21[[#This Row],[interest]] -> 363.29376 | I38: =Table21[[#This Row],[opening balance]]-Table21[[#This Row],[principal paid]]-5000 -> 32998.456
D39: =D38+1 -> 37 | E39: =I38 -> 32998.456 | F39: =$B$6 -> 555.10251 | G39: =(6%/12)*Table21[[#This Row],[opening balance]] -> 164.99228 | H39: =Table21[[#This Row],[monhly installment]]-Table21[[#This Row],[interest]] -> 390.11023 | I39: =Table21[[#This Row],[opening balance]]-Table21[[#This Row],[principal paid]] -> 32608.345
D40: =D39+1 -> 38 | E40: =I39 -> 32608.345 | F40: =$B$6 -> 555.10251 | G40: =(6%/12)*Table21[[#This Row],[opening balance]] -> 163.04173 | H40: =Table21[[#This Row],[monhly installment]]-Table21[[#This Row],[interest]] -> 392.06078 | I40: =Table21[[#This Row],[opening balance]]-Table21[[#This Row],[principal paid]] -> 32216.285
D41: =D40+1 -> 39 | E41: =I40 -> 32216.285 | F41: =$B$6 -> 555.10251 | G41: =(6%/12)*Table21[[#This Row],[opening balance]] -> 161.08142 | H41: =Table21[[#This Row],[monhly installment]]-Table21[[#This Row],[interest]] -> 394.02109 | I41: =Table21[[#This Row],[opening balance]]-Table21[[#This Row],[principal paid]] -> 31822.264
D42: =D41+1 -> 40 | E42: =I41 -> 31822.264 | F42: =$B$6 -> 555.10251 | G42: =(6%/12)*Table21[[#This Row],[opening balance]] -> 159.11132 | H42: =Table21[[#This Row],[monhly installment]]-Table21[[#This Row],[interest]] -> 395.99119 | I42: =Table21[[#This Row],[opening balance]]-Table21[[#This Row],[principal paid]] -> 31426.272
D43: =D42+1 -> 41 | E43: =I42 -> 31426.272 | F43: =$B$6 -> 555.10251 | G43: =(6%/12)*Table21[[#This Row],[opening balance]] -> 157.13136 | H43: =Table21[[#This Row],[monhly installment]]-Table21[[#This Row],[interest]] -> 397.97115 | I43: =Table21[[#This Row],[opening balance]]-Table21[[#This Row],[principal paid]] -> 31028.301
D44: =D43+1 -> 42 | E44: =I43 -> 31028.301 | F44: =$B$6 -> 555.10251 | G44: =(6%/12)*Table21[[#This Row],[opening balance]] -> 155.14151 | H44: =Table21[[#This Row],[monhly installment]]-Table21[[#This Row],[interest]] -> 399.961 | I44: =Table21[[#This Row],[opening balance]]-Table21[[#This Row],[principal paid]] -> 30628.34
D45: =D44+1 -> 43 | E45: =I44 -> 30628.34 | F45: =$B$6 -> 555.10251 | G45: =(6%/12)*Table21[[#This Row],[opening balance]] -> 153.1417 | H45: =Table21[[#This Row],[monhly installment]]-Table21[[#This Row],[interest]] -> 401.96081 | I45: =Table21[[#This Row],[opening balance]]-Table21[[#This Row],[principal paid]] -> 30226.379
D46: =D45+1 -> 44 | E46: =I45 -> 30226.379 | F46: =$B$6 -> 555.10251 | G46: =(6%/12)*Table21[[#This Row],[opening balance]] -> 151.1319 | H46: =Table21[[#This Row],[monhly installment]]-Table21[[#This Row],[interest]] -> 403.97061 | I46: =Table21[[#This Row],[opening balance]]-Table21[[#This Row],[principal paid]] -> 29822.409
D47: =D46+1 -> 45 | E47: =I46 -> 29822.409 | F47: =$B$6 -> 555.10251 | G47: =(6%/12)*Table21[[#This Row],[opening balance]] -> 149.11204 | H47: =Table21[[#This Row],[monhly installment]]-Table21[[#This Row],[interest]] -> 405.99047 | I47: =Table21[[#This Row],[opening balance]]-Table21[[#This Row],[principal paid]] -> 29416.418
D48: =D47+1 -> 46 | E48: =I47 -> 29416.418 | F48: =$B$6 -> 555.10251 | G48: =(6%/12)*Table21[[#This Row],[opening balance]] -> 147.08209 | H48: =Table21[[#This Row],[monhly installment]]-Table21[[#This Row],[interest]] -> 408.02042 | I48: =Table21[[#This Row],[opening balance]]-Table21[[#This Row],[principal paid]] -> 29008.398
D49: =D48+1 -> 47 | E49: =I48 -> 29008.398 | F49: =$B$6 -> 555.10251 | G49: =(6%/12)*Table21[[#This Row],[opening balance]] -> 145.04199 | H49: =Table21[[#This Row],[monhly installment]]-Table21[[#This Row],[interest]] -> 410.06052 | I49: =Table21[[#This Row],[opening balance]]-Table21[[#This Row],[principal paid]] -> 28598.337
D50: =D49+1 -> 48 | E50: =I49 -> 28598.337 | F50: =$B$6 -> 555.10251 | G50: =(6%/12)*Table21[[#This Row],[opening balance]] -> 142.99169 | H50: =Table21[[#This Row],[monhly installment]]-Table21[[#This Row],[interest]] -> 412.11082 | I50: =Table21[[#This Row],[opening balance]]-Table21[[#This Row],[principal paid]] -> 28186.227
... D122: =D121+1 -> 120 | E122: =I121 -> -7011.6872 | F122: =$B$6 -> 555.10251 | G122: =(6%/12)*Table21[[#This Row],[opening balance]] -> -35.058436 | H122: =Table21[[#This Row],[monhly installment]]-Table21[[#This Row],[interest]] -> 590.16095 | I122: =Table21[[#This Row],[opening balance]]-Table21[[#This Row],[principal paid]] -> -7601.8482

Sheet Practice_Problems_2
A1: input | B1: amount | D1: period | E1: opening balance | F1: monthly installment | G1: interest | H1: principal paid | I1: closing balance
A2: loan principal | B2: 250000 | D2: 0 | I2: 250000
A3: interest rates | B3: 0.08 | D3: 1 | E3: =I2 -> 250000 | F3: =$B$6 -> 1834.4114 | G3: =(8%/12)*Table7[[#This Row],[opening balance]] -> 1666.6667 | H3: =Table7[[#This Row],[monthly installment]]-Table7[[#This Row],[interest]] -> 167.74477 | I3: =Table7[[#This Row],[opening balance]]-Table7[[#This Row],[principal paid]] -> 249832.26
A4: n (years) | B4: 30 | D4: =D3+1 -> 2 | E4: =I3 -> 249832.26 | F4: =$B$6 -> 1834.4114 | G4: =(8%/12)*Table7[[#This Row],[opening balance]] -> 1665.5484 | H4: =Table7[[#This Row],[monthly installment]]-Table7[[#This Row],[interest]] -> 168.86307 | I4: =Table7[[#This Row],[opening balance]]-Table7[[#This Row],[principal paid]] -> 249663.39
A5: n (month) | B5: =B4*12 -> 360 | D5: =D4+1 -> 3 | E5: =I4 -> 249663.39 | F5: =$B$6 -> 1834.4114 | G5: =(8%/12)*Table7[[#This Row],[opening balance]] -> 1664.4226 | H5: =Table7[[#This Row],[monthly installment]]-Table7[[#This Row],[interest]] -> 169.98882 | I5: =Table7[[#This Row],[opening balance]]-Table7[[#This Row],[principal paid]] -> 249493.4
A6: monthly instalment | B6: =PMT(B3/12,B5,-B2) -> 1834.4114 | D6: =D5+1 -> 4 | E6: =I5 -> 249493.4 | F6: =$B$6 -> 1834.4114 | G6: =(8%/12)*Table7[[#This Row],[opening balance]] -> 1663.2894 | H6: =Table7[[#This Row],[monthly installment]]-Table7[[#This Row],[interest]] -> 171.12208 | I6: =Table7[[#This Row],[opening balance]]-Table7[[#This Row],[principal paid]] -> 249322.28
A7: outstanding balance at 10th year | B7: =PV(B3/12,B5-(10*12),-B6) -> 219311.76 | D7: =D6+1 -> 5 | E7: =I6 -> 249322.28 | F7: =$B$6 -> 1834.4114 | G7: =(8%/12)*Table7[[#This Row],[opening balance]] -> 1662.1485 | H7: =Table7[[#This Row],[monthly installment]]-Table7[[#This Row],[interest]] -> 172.26289 | I7: =Table7[[#This Row],[opening balance]]-Table7[[#This Row],[principal paid]] -> 249150.02
A8: new interest rates | B8: 0.06 | D8: =D7+1 -> 6 | E8: =I7 -> 249150.02 | F8: =$B$6 -> 1834.4114 | G8: =(8%/12)*Table7[[#This Row],[opening balance]] -> 1661.0001 | H8: =Table7[[#This Row],[monthly installment]]-Table7[[#This Row],[interest]] -> 173.41131 | I8: =Table7[[#This Row],[opening balance]]-Table7[[#This Row],[principal paid]] -> 248976.61
A9: monthly interest rates | B9: =B8/12 -> 0.005 | D9: =D8+1 -> 7 | E9: =I8 -> 248976.61 | F9: =$B$6 -> 1834.4114 | G9: =(8%/12)*Table7[[#This Row],[opening balance]] -> 1659.844 | H9: =Table7[[#This Row],[monthly installment]]-Table7[[#This Row],[interest]] -> 174.56739 | I9: =Table7[[#This Row],[opening balance]]-Table7[[#This Row],[principal paid]] -> 248802.04
A10: remaining n | B10: =B5-(10*12) -> 240 | D10: =D9+1 -> 8 | E10: =I9 -> 248802.04 | F10: =$B$6 -> 1834.4114 | G10: =(8%/12)*Table7[[#This Row],[opening balance]] -> 1658.6803 | H10: =Table7[[#This Row],[monthly installment]]-Table7[[#This Row],[interest]] -> 175.73117 | I10: =Table7[[#This Row],[opening balance]]-Table7[[#This Row],[principal paid]] -> 248626.31
A11: new monthly installment | B11: =PMT(B9,B10,-B7) -> 1571.2176 | D11: =D10+1 -> 9 | E11: =I10 -> 248626.31 | F11: =$B$6 -> 1834.4114 | G11: =(8%/12)*Table7[[#This Row],[opening balance]] -> 1657.5087 | H11: =Table7[[#This Row],[monthly installment]]-Table7[[#This Row],[interest]] -> 176.90271 | I11: =Table7[[#This Row],[opening balance]]-Table7[[#This Row],[principal paid]] -> 248449.41
A12: saved monthly installment | B12: =B6-B11 -> 263.19387 | D12: =D11+1 -> 10 | E12: =I11 -> 248449.41 | F12: =$B$6 -> 1834.4114 | G12: =(8%/12)*Table7[[#This Row],[opening balance]] -> 1656.3294 | H12: =Table7[[#This Row],[monthly installment]]-Table7[[#This Row],[interest]] -> 178.08206 | I12: =Table7[[#This Row],[opening balance]]-Table7[[#This Row],[principal paid]] -> 248271.32
D13: =D12+1 -> 11 | E13: =I12 -> 248271.32 | F13: =$B$6 -> 1834.4114 | G13: =(8%/12)*Table7[[#This Row],[opening balance]] -> 1655.1422 | H13: =Table7[[#This Row],[monthly installment]]-Table7[[#This Row],[interest]] -> 179.26928 | I13: =Table7[[#This Row],[opening balance]]-Table7[[#This Row],[principal paid]] -> 248092.05
D14: =D13+1 -> 12 | E14: =I13 -> 248092.05 | F14: =$B$6 -> 1834.4114 | G14: =(8%/12)*Table7[[#This Row],[opening balance]] -> 1653.947 | H14: =Table7[[#This Row],[monthly installment]]-Table7[[#This Row],[interest]] -> 180.46441 | I14: =Table7[[#This Row],[opening balance]]-Table7[[#This Row],[principal paid]] -> 247911.59
D15: =D14+1 -> 13 | E15: =I14 -> 247911.59 | F15: =$B$6 -> 1834.4114 | G15: =(8%/12)*Table7[[#This Row],[opening balance]] -> 1652.7439 | H15: =Table7[[#This Row],[monthly installment]]-Table7[[#This Row],[interest]] -> 181.6675 | I15: =Table7[[#This Row],[opening balance]]-Table7[[#This Row],[principal paid]] -> 247729.92
D16: =D15+1 -> 14 | E16: =I15 -> 247729.92 | F16: =$B$6 -> 1834.4114 | G16: =(8%/12)*Table7[[#This Row],[opening balance]] -> 1651.5328 | H16: =Table7[[#This Row],[monthly installment]]-Table7[[#This Row],[interest]] -> 182.87862 | I16: =Table7[[#This Row],[opening balance]]-Table7[[#This Row],[principal paid]] -> 247547.04
D17: =D16+1 -> 15 | E17: =I16 -> 247547.04 | F17: =$B$6 -> 1834.4114 | G17: =(8%/12)*Table7[[#This Row],[opening balance]] -> 1650.3136 | H17: =Table7[[#This Row],[monthly installment]]-Table7[[#This Row],[interest]] -> 184.09781 | I17: =Table7[[#This Row],[opening balance]]-Table7[[#This Row],[principal paid]] -> 247362.95
D18: =D17+1 -> 16 | E18: =I17 -> 247362.95 | F18: =$B$6 -> 1834.4114 | G18: =(8%/12)*Table7[[#This Row],[opening balance]] -> 1649.0863 | H18: =Table7[[#This Row],[monthly installment]]-Table7[[#This Row],[interest]] -> 185.32513 | I18: =Table7[[#This Row],[opening balance]]-Table7[[#This Row],[principal paid]] -> 247177.62
